Workbook

Sheet 0_PRIDEL
A1: Rozpočet FM na rok 2024
E3: ROZPOČET TUL na 2024 (KVE: NavRoz24.xls)
A4: Zde přesné částky od KVE (rozpočet TUL vpravo): | B4: činn. 106: | E4: Fakulta | F4: FM | G4: korekce na FM | H4: *1000 | J4: 2023
A5: A | B5: =H5 -> 40511813 | E5: A | F5: 40511.813 | H5: =F5*1000-G5 -> 40511813 | J5: 43779534
A6: Úpravy | B6: =H6 -> 0 | E6: Úpravy | F6: 0 | H6: =F6*1000-G6 -> 0 | J6: 0
A7: Úpravy za učebny | B7: =H7 -> 0 | E7: Úpravy za učebny | F7: 0 | H7: =F7*1000-G7 -> 0 | J7: 0
A8: Odpočet | B8: =H8 -> -57272.727 | E8: Odpočet | F8: -57.272727 | H8: =F8*1000-G8 -> -57272.727 | J8: -44758.91
A9: Služby poskytované | B9: =H9 -> 3839784.5 | E9: Spos | F9: 3839.7845 | H9: =F9*1000 -> 3839784.5 | J9: 4943481.1
A10: Služby přijímané | B10: =H10 -> -9016180.8 | E10: Spři | F10: -9016.1808 | H10: =F10*1000 -> -9016180.8 | J10: -10225560
A11: K | B11: =H11 -> 11891886 | E11: K | F11: 11891.886 | G11: 0 | H11: =F11*1000-G11 -> 11891886 | J11: 10334001
A12: KVE v RozFak.xls: OK (nezaokrouhleno na tis.) | B12: =SUM(B5:B11) -> 47170030 | E12: IP stabilitační | F12: 7080.4716 | G12: 0 | H12: =F12*1000-G12 -> 7080471.6 | J12: 13435927
E13: IP motivační | F13: 14251.849 | G13: 0 | H13: =F13*1000-G13 -> 14251849 | J13: 10990671
E14: SV | F14: 4406.9596 | G14: 0 | H14: =F14*1000-G14 -> 4406959.6 | J14: 4959130.7
E15: Celkem | F15: =SUM(F5:F14) -> 72909.311 | H15: =F15*1000 -> 72909311 | J15: 78172425
A16: Příděly | E16: Činn. 106 | J16: =H15-J15 -> -5263114.8
A17: 106 příděl z MŠMT | B17: =B12 -> 47170030 | E17: =SUM(F5:F11) -> 47170.03
A18: Podpora FoM (úprava na vstupu) | B18: 150000 | E18: Fakulta | F18: FM | J18: 2023
A19: 106 k ROZDĚLENÍ (po úpravách na vstupu) | B19: =B17-B18 -> 47020030 | E19: Režie | F19: 22264.176 | H19: =F19*1000 -> 22264176 | J19: 22264176
A20: IP 117 | B20: =H12+H13 -> 21332321 | E20: Přepočet na provedené dislokace 2023 - rozdíl | F20: -124.15407 | H20: =F20*1000 -> -124154.07 | J20: 429970.57
A21: SV 115 | B21: =H14 -> 4406959.6 | E21: Režie upravené o dislokace (bez Režie AS) | F21: =SUM(F19:F20) -> 22140.022 | H21: =F21*1000 -> 22140022 | J21: 22694147
A22: Celkem 106, 117 | B22: =SUM(B19:B20) -> 68352351 | E22: Režie AS | F22: 25 | H22: =F22*1000 -> 25000 | J22: 25000
A23: Režie celoškolská | B23: =-H21-H22 -> -22165022 | E23: Fakulta | F23: FM
A24: Podíl na úhradě FRIM 20% (dle užívaných ploch) | B24: =-H26 -> -476505.68 | E24: uživatel | F24: 3332471
A25: Celkem 106, 117, mínus odvody REK | B25: =SUM(B22:B24) -> 45710823 | E25: PUČ [m2] | F25: 3861.7 | H25: =F25 -> 3861.7 | J25: 4067.36
B26: =B25-ROZPOČET!G13 -> 0.14841125 | E26: FRIM [Kč] | F26: 476.50568 | H26: =F26*1000 -> 476505.68 | J26: 517984.39
F28: =F5+F6+F7+F8+F9+F10+F11+F12+F13-F19-F20 -> 46362.329 | H28: =H5+H6+H7+H8+H9+H10+H11+H12+H13-H19-H20 -> 46362329 | J28: =J5+J6+J7+J8+J9+J10+J11+J12+J13-J19-J20 -> 50519148

Sheet 1_Bc_Mag_DSP
A1: Rozdělení dotace (celé) na vzdělávací činnost - 106 - podle počtu bak., magisterských studentů a doktorandů na rok 2023/2024
B3: K rozdělení: | C3: ='10_Celkem_106'!D7 -> 45859844
B5: Počet celkem (průměr za poslední 3 roky - vždy dle stavu k 31. 10.) | C5: Koeficient náročnosti studia | D5: Počet studentů * Koeficient | E5: % | F5: Kč | G5: B+NM
A6: B | B6: =B31 -> 361.66667 | C6: 0.8 | D6: =B6*C6 -> 289.33333 | E6: =D6/$D$9 -> 0.5122455 | F6: =$C$3*E6 -> 23491499 | H6: =F6/$F$9 -> 0.5122455
A7: NM | B7: =B32 -> 136.66667 | C7: 1.2 | D7: =B7*C7 -> 164 | E7: =D7/$D$9 -> 0.29035114 | F7: =$C$3*E7 -> 13315458 | G7: =SUM(F6:F7) -> 36806956 | H7: =F7/$F$9 -> 0.29035114 | I7: =G7/$F$9 -> 0.80259664
A8: DSP | B8: =B33 -> 74.333333 | C8: 1.5 | D8: =B8*C8 -> 111.5 | E8: =D8/$D$9 -> 0.19740336 | F8: =$C$3*E8 -> 9052887.4 | H8: =F8/$F$9 -> 0.19740336 | I8: =F8/$F$9 -> 0.19740336
B9: =SUM(B6:B8) -> 572.66667 | D9: =SUM(D6:D8) -> 564.83333 | E9: =SUM(E6:E8) -> 1 | F9: =SUM(F6:F8) -> 45859844 | H9: =SUM(H6:H8) -> 1 | I9: =SUM(I7:I8) -> 1
F10: =F9-C3 -> 0
F12: ='10_Celkem_106'!#REF! -> #REF!
F14: =SUM(F12:F13) -> #REF!
E15: DFM: | F15: 0
F16: =SUM(F14:F15) -> #REF!
E18: DFM 116: | F18: 0
E19: DFM 106: | F19: =-F15 -> 0
E20: DFM: | F20: =SUM(F18:F19) -> 0
A23: B - bakalářské studijní programy
A24: NM - navazující magisterské studijní programy (2leté)
A25: DSP - doktorské studijní programy
A27: Výpočet počtu studentů pro stanovení přídělu na BS/MS/DS | D27: počty ze STAGu
D28: 2023/2024 | E28: 2022/2023 | F28: 2021/2022 | G28: 2020/2021
D29: 45230 | E29: 44865 | F29: 44500 | G29: 44135
B30: Prům. | D30: 2023 | E30: 2022 | F30: 2021 | G30: 2020
A31: B | B31: =AVERAGE(D31:F31) -> 361.66667 | D31: 348 | E31: 378 | F31: 359 | G31: 344
A32: NM | B32: =AVERAGE(D32:F32) -> 136.66667 | D32: 139 | E32: 145 | F32: 126 | G32: 118
A33: DSP | B33: =AVERAGE(D33:F33) -> 74.333333 | D33: 68 | E33: 80 | F33: 75 | G33: 56
B34: =SUM(B31:B33) -> 572.66667 | D34: =SUM(D31:D33) -> 555 | E34: 603 | F34: =SUM(F31:F33) -> 560 | G34: =SUM(G31:G33) -> 518
D36: změna počtu studentů
D37: =D31/E31 -> 0.92063492 | E37: =E31/F31 -> 1.0529248 | F37: =F31/G31 -> 1.0436047
D38: =D32/E32 -> 0.95862069 | E38: =E32/F32 -> 1.1507937 | F38: =F32/G32 -> 1.0677966
D39: =D33/E33 -> 0.85 | E39: =E33/F33 -> 1.0666667 | F39: =F33/G33 -> 1.3392857
D40: =D34/E34 -> 0.92039801 | E40: =E34/F34 -> 1.0767857 | F40: =F34/G34 -> 1.0810811

Sheet 2_Projekty_BP_DP
A1: Počty vedených projektů, bakalářských a diplomových prací za akad. rok 2023/2024
A3: upravený | B3: 8000 | C3: 8000 | D3: 12000 | E3: 14000
A4: Ústav | B4: Počet Bc.-projektů | C4: Počet Mgr.-projektů | D4: Počet BP vedených na FM | E4: Počet DP vedených na FM | F4: Počet Bc.-projektů * Kč | G4: Počet Mgr.-projektů * Kč | H4: Počet BP vedených na FM * Kč | I4: Počet DP vedených na FM * Kč | J4: Ústav celkem
A5: ITE, 7620 | B5: =MAX(M21:N21)+O21+P21+Q21+R21 -> 16 | C5: =Z21+MAX(AA21:AB21) -> 0 | D5: =MAX(S21:T21)+MAX(U21:V21)+MAX(W21:X21)+Y21 -> 10 | E5: =MAX(AC21:AD21)+MAX(AE21:AF21)+MAX(AG21:AH21)+MAX(AI21:AJ21)+AK21+AL21 -> 6 | F5: =B5*$B$3 -> 128000 | G5: =C5*$C$3 -> 0 | H5: =D5*$D$3 -> 120000 | I5: =E5*$E$3 -> 84000 | J5: =SUM(F5:I5) -> 332000 | L5: 388000
A6: MTI, 7630 | B6: =MAX(M22:N22)+O22+P22+Q22+R22 -> 20 | C6: =Z22+MAX(AA22:AB22) -> 7 | D6: =MAX(S22:T22)+MAX(U22:V22)+MAX(W22:X22)+Y22 -> 68 | E6: =MAX(AC22:AD22)+MAX(AE22:AF22)+MAX(AG22:AH22)+MAX(AI22:AJ22)+AK22+AL22 -> 50 | F6: =B6*$B$3 -> 160000 | G6: =C6*$C$3 -> 56000 | H6: =D6*$D$3 -> 816000 | I6: =E6*$E$3 -> 700000 | J6: =SUM(F6:I6) -> 1732000 | L6: 1284000
A7: NTI, 7640 | B7: =MAX(M23:N23)+O23+P23+Q23+R23 -> 24 | C7: =Z23+MAX(AA23:AB23) -> 0 | D7: =MAX(S23:T23)+MAX(U23:V23)+MAX(W23:X23)+Y23 -> 22 | E7: =MAX(AC23:AD23)+MAX(AE23:AF23)+MAX(AG23:AH23)+MAX(AI23:AJ23)+AK23+AL23 -> 15 | F7: =B7*$B$3 -> 192000 | G7: =C7*$C$3 -> 0 | H7: =D7*$D$3 -> 264000 | I7: =E7*$E$3 -> 210000 | J7: =SUM(F7:I7) -> 666000 | L7: 154000
B8: =SUM(B5:B7) -> 60 | C8: =SUM(C5:C7) -> 7 | D8: =SUM(D5:D7) -> 100 | E8: =SUM(E5:E7) -> 71 | F8: =SUM(F5:F7) -> 480000 | G8: =SUM(G5:G7) -> 56000 | H8: =SUM(H5:H7) -> 1200000 | I8: =SUM(I5:I7) -> 994000 | J8: =SUM(J5:J7) -> 2730000
F9: B: | G9: =F8+H8 -> 1680000
F10: NM: | G10: =G8+I8 -> 1050000
G11: =SUM(G9:G10) -> 2730000
I13: Vypočt. dotace na I.-III.roč., IV. a V. roč. (vč.navazujících) | J13: ='1_Bc_Mag_DSP'!F6+'1_Bc_Mag_DSP'!F7 -> 36806956
I14: na Projekty+BP+DP vyčleněno | J14: =J8 -> 2730000 | K14: =J14/$J$13 -> 0.074170762
I15: K dalšímu dělení za výuku zbývá: | J15: =J13-J14 -> 34076956 | K15: =J15/$J$13 -> 0.92582924
M19: Bak. projekty | S19: Bak. práce | Z19: Mag. projekt | AC19: Diplomky
L20: Název předmětu | M20: PRJ1 | N20: PRJ2 | O20: PRJ | P20: PR1 | Q20: PRJA | R20: PRN | S20: BP1 | T20: BP2 | U20: BPA1 | V20: BPA2 | W20: BP-1 | X20: BP-2 | Y20: BPN | Z20: PRO | AA20: PD1 | AB20: PD2 | AC20: DP1 | AD20: DP2 | AE20: DPA1 | AF20: DPA2 | AG20: DP-1 | AH20: DP-2 | AI20: DP1-Z | AJ20: DP2-Z | AK20: DPN | AL20: DPR
L21: ITE, 7620 | M21: 0 | N21: 0 | O21: 16 | P21: 0 | Q21: 0 | R21: 0 | S21: 6 | T21: 7 | U21: 0 | V21: 0 | W21: 3 | X21: 3 | Y21: 0 | Z21: 0 | AA21: 0 | AB21: 0 | AC21: 0 | AD21: 0 | AE21: 0 | AF21: 0 | AG21: 5 | AH21: 6 | AI21: 0 | AJ21: 0 | AK21: 0 | AL21: 0
L22: MTI, 7630 | M22: 0 | N22: 0 | O22: 20 | P22: 0 | Q22: 0 | R22: 0 | S22: 29 | T22: 30 | U22: 0 | V22: 0 | W22: 38 | X22: 38 | Y22: 0 | Z22: 5 | AA22: 2 | AB22: 2 | AC22: 4 | AD22: 4 | AE22: 1 | AF22: 1 | AG22: 41 | AH22: 41 | AI22: 0 | AJ22: 0 | AK22: 1 | AL22: 3
L23: NTI, 7640 | M23: 0 | N23: 0 | O23: 19 | P23: 0 | Q23: 4 | R23: 1 | S23: 18 | T23: 17 | U23: 1 | V23: 1 | W23: 0 | X23: 0 | Y23: 3 | Z23: 0 | AA23: 0 | AB23: 0 | AC23: 1 | AD23: 1 | AE23: 0 | AF23: 1 | AG23: 13 | AH23: 13 | AI23: 0 | AJ23: 0 | AK23: 0 | AL23: 0
L25: Vyplní SO b+m
L26: portál STAG - prohlížení - předmět - zkratka předmětu

Sheet 3_DSP
A1: Příděl části dotace na vzdělávací činnost (činnost 106) podle počtu doktorandů (studujících standardní dobu studia + 1 rok = SDS+1) na rok 2024
A2: Kritérium: vykonaná/nevykonaná státní doktorská zkouška a počet absolventů
C4: Počet bodů | J4: Vypočtená částka na DSP | L4: ='1_Bc_Mag_DSP'!F8 -> 9052887.4
C5: 5 | D5: 2 | E5: 1
A6: Ústav | B6: Počet dokt. do (SDS+1) celkem | C6: Počet absolventů za posl. 3 roky | D6: Počet dokt. do SDS+1 se st. dokt. zk | E6: Počet dokt. do SDS+1 bez st. dokt. zk | F6: Počet abs. * Počet bodů | G6: Počet dokt. se st. dokt. zk.* Počet bodů | H6: Počet dokt. bez st. dokt. zk. * Počet bodů | I6: (Počet dokt. + Absolvetů) * Počet bodů celkem | J6: % | K6: % FM/ext | L6: Kč | M6: korekce pro FM na vrub CXI a FP | O6: po korekci
A7: ITE, 7620 | B7: 3 | C7: 4 | D7: 1 | E7: 2 | F7: =C7*$C$5 -> 20 | G7: =D7*$D$5 -> 2 | H7: =E7*$E$5 -> 2 | I7: =SUM(F7:H7) -> 24 | J7: =I7/$I$14 -> 0.13953488 | K7: =I7/SUM($I$7:$I$10) -> 0.18320611 | L7: =$L$4*J7 -> 1263193.6 | O7: =L7+$M$10*(1-$N$10)*K7 -> 1511979.4
A8: MTI, 7630 | B8: 10 | C8: 4 | D8: 2 | E8: 8 | F8: =C8*$C$5 -> 20 | G8: =D8*$D$5 -> 4 | H8: =E8*$E$5 -> 8 | I8: =SUM(F8:H8) -> 32 | J8: =I8/$I$14 -> 0.18604651 | K8: =I8/SUM($I$7:$I$10) -> 0.24427481 | L8: =$L$4*J8 -> 1684258.1 | O8: =L8+$M$10*(1-$N$10)*K8 -> 2015972.5
A9: NTI, 7640 | B9: 27 | C9: 9 | D9: 3 | E9: 24 | F9: =C9*$C$5 -> 45 | G9: =D9*$D$5 -> 6 | H9: =E9*$E$5 -> 24 | I9: =SUM(F9:H9) -> 75 | J9: =I9/$I$14 -> 0.43604651 | K9: =I9/SUM($I$7:$I$10) -> 0.57251908 | L9: =$L$4*J9 -> 3947480 | O9: =L9+$M$10*(1-$N$10)*K9 -> 4724935.6
A10: DFM, 7817 | B10: 0 | C10: 0 | D10: 0 | E10: 0 | F10: =C10*$C$5 -> 0 | G10: =D10*$D$5 -> 0 | H10: =E10*$E$5 -> 0 | I10: =SUM(F10:H10) -> 0 | J10: =I10/$I$14 -> 0 | K10: =I10/SUM($I$7:$I$10) -> 0 | L10: =$L$4*J10 -> 0 | M10: =SUM(L11:L13) -> 2157955.7 | N10: 0.37072118 | O10: =M10*N10 -> 799999.89 | Q10: režie za studenty CXI a FP
A11: CXI | B11: 1 | C11: 6 | D11: 0 | E11: 1 | F11: =C11*$C$5 -> 30 | G11: =D11*$D$5 -> 0 | H11: =E11*$E$5 -> 1 | I11: =SUM(F11:H11) -> 31 | J11: =I11/$I$14 -> 0.18023256 | K11: =I11/SUM($I$11:$I$13) -> 0.75609756 | L11: =$L$4*J11 -> 1631625.1 | O11: =L11/SUM($L$11:$L$13)*(SUM($L$11:$L$13)-$M$10) -> 0 | Q11: ="Převod 106 na "&A11 -> Převod 106 na CXI
A12: KCH | B12: 8 | C12: 0 | D12: 1 | E12: 7 | F12: =C12*$C$5 -> 0 | G12: =D12*$D$5 -> 2 | H12: =E12*$E$5 -> 7 | I12: =SUM(F12:H12) -> 9 | J12: =I12/$I$14 -> 0.052325581 | K12: =I12/SUM($I$11:$I$13) -> 0.2195122 | L12: =$L$4*J12 -> 473697.6 | O12: =L12/SUM($L$11:$L$13)*(SUM($L$11:$L$13)-$M$10) -> 0 | Q12: ="Převod 106 na "&A12 -> Převod 106 na KCH
A13: KFY | B13: 1 | C13: 0 | D13: 0 | E13: 1 | F13: =C13*$C$5 -> 0 | G13: =D13*$D$5 -> 0 | H13: =E13*$E$5 -> 1 | I13: =SUM(F13:H13) -> 1 | J13: =I13/$I$14 -> 0.0058139535 | K13: =I13/SUM($I$11:$I$13) -> 0.024390244 | L13: =$L$4*J13 -> 52633.066 | O13: =L13/SUM($L$11:$L$13)*(SUM($L$11:$L$13)-$M$10) -> 0 | Q13: ="Převod 106 na "&A13 -> Převod 106 na KFY
B14: =SUM(B7:B13) -> 50 | C14: =SUM(C7:C13) -> 23 | D14: =SUM(D7:D13) -> 7 | E14: =SUM(E7:E13) -> 43 | F14: =SUM(F7:F13) -> 115 | G14: =SUM(G7:G13) -> 14 | H14: =SUM(H7:H13) -> 43 | I14: =SUM(I7:I13) -> 172 | J14: =SUM(J7:J10) -> 0.76162791 | K14: n/a | L14: =SUM(L7:L13) -> 9052887.4 | M14: =SUM(M7:M13) -> 2157955.7 | O14: =SUM(O7:O13) -> 9052887.4
J15: kontrola | L15: =L4-L14 -> 0 | O15: =L4-O14 -> 0
O16: =SUM(O11:O13) -> 0 | Q16: Celkem MIMO FM
B19: nn | C19: zkopírováno z tabulky od SO-DSP (DOKTORANDI_FM_REK_ROZPOČET_2024_fin.xlsx) | M19: nn | N19: rozhodnutí děkana

Sheet 4_DOC_PROF
A1: Příděl části dotace podle počtu kvalifikační struktury DOC a PROF | F1: 2024
A2: Kritérium: jmenovaný DOC/PROF jako zaměstnanec FM "A")
D4: Roční ocenění
D5: 60000 | E5: 80000
A6: Ústav | B6: Počet doc. celkem | C6: Počet prof. celkem | D6: Počet doc. za posl. 3 roky | E6: Počet prof. za 3 roky | F6: Počet doc. * roční ocenění | G6: Počet prof. * roční ocenění | H6: % | I6: Kč | K6: Z činn. 106 | L6: Z činn. 117
A7: ITE, 7620 | B7: 2 | C7: 4 | D7: 1 | E7: 0 | F7: =D7*$D$5 -> 60000 | G7: =E7*$E$5 -> 0 | H7: =(F7+G7)/$H$10 -> 0.5 | I7: =F7+G7 -> 60000 | K7: =H7*$I$15 -> 30000 | L7: =H7*$I$16 -> 30000
A8: MTI, 7630 | B8: 5 | C8: 4 | D8: 1 | E8: 0 | F8: =D8*$D$5 -> 60000 | G8: =E8*$E$5 -> 0 | H8: =(F8+G8)/$H$10 -> 0.5 | I8: =F8+G8 -> 60000 | K8: =H8*$I$15 -> 30000 | L8: =H8*$I$16 -> 30000
A9: NTI, 7640 | B9: 8 | C9: 1 | D9: 0 | E9: 0 | F9: =D9*$D$5 -> 0 | G9: =E9*$E$5 -> 0 | H9: =(F9+G9)/$H$10 -> 0 | I9: =F9+G9 -> 0 | K9: =H9*$I$15 -> 0 | L9: =H9*$I$16 -> 0
B10: =SUM(B7:B9) -> 15 | C10: =SUM(C7:C9) -> 9 | D10: =SUM(D7:D9) -> 2 | E10: =SUM(E7:E9) -> 0 | F10: =SUM(F7:F9) -> 120000 | G10: =SUM(G7:G9) -> 0 | H10: =F10+G10 -> 120000 | I10: =SUM(I7:I9) -> 120000
H14: % ze 106 | I14: 0.5
H15: odebrat ze 106 | I15: =I10*I14 -> 60000 | P15: EXTERNISTI se nikomu nezapočítají
H16: odebrat ze 117 | I16: =I10*(1-I14) -> 60000 | P16: profesoři
I17: =SUM(I15:I16) -> 120000 | Q17: 2023 | R17: 0
A18: Poznámka: | Q18: 2022 | R18: 0
A19: Celkový počet doc. a prof. je brán ze mzdové inventury platné k 31.12.2023 | Q19: 2021 | R19: 0
A20: Výčet profesorů a docentů pro započtení je rozhodný termín jmenování
P23: docenti
Q24: 2023 | R24: 0 | S24: Posel 11.7.23 (externí)
Q25: 2022 | R25: 2 | S25: Žídek 1.7.22 (externí), Červa 1.1.22 (ITE), Yalcinkaya 1.1.22 (MTI), Salač 1.7.22 (FP)
Q26: 2021 | R26: 0 | S26: Pustka1.1.21 (externí)

Sheet 4a_úvazky-na-FM
A1: Příděl části dotace podle kvalifikační struktury
A3: k 31. 12. 2023
A4: Tabulka kvalifikační struktury | C4: Úvazky FM | G4: kolik procent odebrat na kvalif. strukturu | H4: 0.015 | L4: Úvazky FM | O4: Úvazky FM k 31. 12. 2023
A5: Ústav | B5: 111 | C5: 113 | D5: 114 | G5: % ze součtu (106+117) | H5: =('0_PRIDEL'!B19+'0_PRIDEL'!B20)*H4 -> 1025285.3 | L5: 111 | M5: 113 | N5: 114 | O5: Celkem
A6: ITE, 7620 | B6: =L6 -> 4 | C6: =M6 -> 2 | D6: =N6 -> 7.1 | G6: % ze 106 | H6: 0.5 | L6: 4 | M6: 2 | N6: 7.1 | O6: =SUM(L6:N6) -> 13.1 | P6: ITE, 7620
A7: MTI, 7630 | B7: =L7 -> 2.25 | C7: =M7 -> 5 | D7: =N7 -> 21.4 | G7: odebrat ze 106 | H7: =H6*SUM(F24:F26) -> 512642.63 | L7: 2.25 | M7: 5 | N7: 21.4 | O7: =SUM(L7:N7) -> 28.65 | P7: MTI, 7630
A8: NTI, 7640 | B8: =L8 -> 0.3 | C8: =M8 -> 8 | D8: =N8 -> 13.55 | G8: odebrat ze 117 | H8: =(1-H6)*SUM(F24:F26) -> 512642.63 | L8: 0.3 | M8: 8 | N8: 13.55 | O8: =SUM(L8:N8) -> 21.85 | P8: NTI, 7640
L9: =SUM(L6:L8) -> 6.55 | M9: =SUM(M6:M8) -> 15 | N9: =SUM(N6:N8) -> 42.05
B10: Tarify tříd (dolní hranice) | L10: Hlavy FM
B11: 50000 | C11: 40000 | D11: 35000 | H11: Akademičtí pracovníci | L11: 111 | M11: 113 | N11: 114 | O11: Celkem
A12: Ústav | B12: 111 | C12: 113 | D12: 114 | G12: 111 | H12: profesor | L12: 4 | M12: 2 | N12: 8 | O12: =SUM(L12:N12) -> 14 | P12: ITE, 7620
A13: ITE, 7620 | B13: =B6*B$11 -> 200000 | C13: =C6*C$11 -> 80000 | D13: =D6*D$11 -> 248500 | G13: 113 | H13: docent | L13: 4 | M13: 5 | N13: 27 | O13: =SUM(L13:N13) -> 36 | P13: MTI, 7630
A14: MTI, 7630 | B14: =B7*B$11 -> 112500 | C14: =C7*C$11 -> 200000 | D14: =D7*D$11 -> 749000 | G14: 114 | H14: odborný asistent s vědeckou hodností | L14: 1 | M14: 8 | N14: 17 | O14: =SUM(L14:N14) -> 26 | P14: NTI, 7640
A15: NTI, 7640 | B15: =B8*B$11 -> 15000 | C15: =C8*C$11 -> 320000 | D15: =D8*D$11 -> 474250 | G15: 115 | H15: odborný asistent bez vědecké hodnosti | L15: =SUM(L12:L14) -> 9 | M15: =SUM(M12:M14) -> 15 | N15: =SUM(N12:N14) -> 52
G16: 117 | H16: asistent výzkumu, lektor
A17: Ústav | B17: 111 | C17: 113 | D17: 114 | G17: 121 | H17: technický pracovník | L17: Pozn. Dle souboru mi_FM: počítat dle skutečných hodnot, NE dle přepočtů
A18: ITE, 7620 | B18: =B13/SUM($B$13:$D$15) -> 0.083359383 | C18: =C13/SUM($B$13:$D$15) -> 0.033343753 | D18: =D13/SUM($B$13:$D$15) -> 0.10357403 | G18: 131 | H18: administrativní pracovník | L18: brát poslední inventuru v roce (data k 31.12.2023 pro stanovení rozpočtu na 2024)
A19: MTI, 7630 | B19: =B14/SUM($B$13:$D$15) -> 0.046889653 | C19: =C14/SUM($B$13:$D$15) -> 0.083359383 | D19: =D14/SUM($B$13:$D$15) -> 0.31218089
A20: NTI, 7640 | B20: =B15/SUM($B$13:$D$15) -> 0.0062519537 | C20: =C15/SUM($B$13:$D$15) -> 0.13337501 | D20: =D15/SUM($B$13:$D$15) -> 0.19766594
B22: Přepočet na 10% přídělu
A23: Ústav | B23: 111 | C23: 113 | D23: 114 | F23: Vrátit na ústavy | G23: z toho 106 | H23: z toho 117
A24: ITE, 7620 | B24: =B18*$H$5 -> 85467.147 | C24: =C18*$H$5 -> 34186.859 | D24: =D18*$H$5 -> 106192.93 | F24: =SUM(B24:D24) -> 225846.94 | G24: =F24*$H$6 -> 112923.47 | H24: =F24*(1-$H$6) -> 112923.47
A25: MTI, 7630 | B25: =B19*$H$5 -> 48075.27 | C25: =C19*$H$5 -> 85467.147 | D25: =D19*$H$5 -> 320074.47 | F25: =SUM(B25:D25) -> 453616.88 | G25: =F25*$H$6 -> 226808.44 | H25: =F25*(1-$H$6) -> 226808.44
A26: NTI, 7640 | B26: =B20*$H$5 -> 6410.036 | C26: =C20*$H$5 -> 136747.44 | D26: =D20*$H$5 -> 202663.97 | F26: =SUM(B26:D26) -> 345821.44 | G26: =F26*$H$6 -> 172910.72 | H26: =F26*(1-$H$6) -> 172910.72
F27: =SUM(F24:F26) -> 1025285.3 | G27: =SUM(G24:G26) -> 512642.63 | H27: =SUM(H24:H26) -> 512642.63
F28: kontrola | G28: =G27-H7 -> 0 | H28: =H27-H8 -> 0

Sheet 5_Výuka
A1: 2023-24
A2: Výuka v zimním semestru | D2: BS | E2: I.-III. | F2: 1.2 | G2: 1 | H2: 0.8
A3: Výuka v letním semestru | D3: NMS | E3: IV.- V. | F3: 1.2 | G3: 1 | H3: 0.8
A5: ITE | B5: Počet studentů na předmětu | C5: Počet hodin přednášek za celý semestr | D5: Počet hodin cvičení za celý semestr | E5: Počet kroužků ke cvičení ze STAGu | F5: Před. *Koef.Př. | G5: Cvič.pro první 2 kroužky * Koef.Cv.1 | H5: Cvič. pro 3. a další kroužky * Koef.Cv.2 | I5: Body celkem | K5: Poznámky
A6: I. ročník
A7: Výpočty, simul. a vizual. Matlab MTLB (100) | B7: 75 | C7: 14 | D7: 28 | E7: 4 | F7: =IF(B7=0,0*C7*$F$2,C7*$F$2) -> 16.8 | G7: {=IF(E7=0,0,IF(E7=1,D7*$G$2,D7*$G$2*2))} -> 56 | H7: {=IF(E7>2,D7*(E7-2)*$H$2,0)} -> 44.8 | I7: =SUM(F7:H7) -> 117.6 | J7: B
A8: Číslicová technika CITE (79) | B8: 55 | C8: 28 | D8: 28 | E8: 5 | F8: =IF(B8=0,0*C8*$F$2,C8*$F$2) -> 33.6 | G8: {=IF(E8=0,0,IF(E8=1,D8*$G$2,D8*$G$2*2))} -> 56 | H8: {=IF(E8>2,D8*(E8-2)*$H$2,0)} -> 67.2 | I8: =SUM(F8:H8) -> 156.8 | J8: B
A9: Elektronická dokumentace EDK (73) | B9: 56 | C9: 14 | D9: 14 | E9: 2 | F9: =IF(B9=0,0*C9*$F$2,C9*$F$2) -> 16.8 | G9: {=IF(E9=0,0,IF(E9=1,D9*$G$2,D9*$G$2*2))} -> 28 | H9: {=IF(E9>2,D9*(E9-2)*$H$2,0)} -> 0 | I9: =SUM(F9:H9) -> 44.8 | J9: B | K9: Lichy/sudy
A10: II. ročník | I10: =SUM(I7:I9) -> 319.2
A11: Signály a informace SGI (84) | B11: 98 | C11: 28 | D11: 28 | E11: 5 | F11: =IF(B11=0,0*C11*$F$2,C11*$F$2) -> 33.6 | G11: {=IF(E11=0,0,IF(E11=1,D11*$G$2,D11*$G$2*2))} -> 56 | H11: {=IF(E11>2,D11*(E11-2)*$H$2,0)} -> 67.2 | I11: =SUM(F11:H11) -> 156.8 | J11: B
A12: FZS - Úvod do syst. a signálů USS*Z (8) | B12: 22 | C12: 28 | D12: 28 | E12: 2 | F12: =IF(B12=0,0*C12*$F$2,C12*$F$2) -> 33.6 | G12: {=IF(E12=0,0,IF(E12=1,D12*$G$2,D12*$G$2*2))} -> 56 | H12: {=IF(E12>2,D12*(E12-2)*$H$2,0)} -> 0 | I12: =SUM(F12:H12) -> 89.6 | J12: B | K12: 19.3
A13: Databáze pro big data DPB (33) | B13: 44 | C13: 28 | D13: 28 | E13: 2 | F13: =IF(B13=0,0*C13*$F$2,C13*$F$2) -> 33.6 | G13: {=IF(E13=0,0,IF(E13=1,D13*$G$2,D13*$G$2*2))} -> 56 | H13: {=IF(E13>2,D13*(E13-2)*$H$2,0)} -> 0 | I13: =SUM(F13:H13) -> 89.6 | J13: B
A14: Základy elektroniky ZELB (10) | B14: 3 | C14: 28 | D14: 28 | E14: 1 | F14: =IF(B14=0,0*C14*$F$2,C14*$F$2) -> 33.6 | G14: {=IF(E14=0,0,IF(E14=1,D14*$G$2,D14*$G$2*2))} -> 28 | H14: {=IF(E14>2,D14*(E14-2)*$H$2,0)} -> 0 | I14: =SUM(F14:H14) -> 61.6 | J14: B
A15: Základy konstruování ZKO (38) | B15: 42 | C15: 14 | D15: 14 | E15: 3 | F15: =IF(B15=0,0*C15*$F$2,C15*$F$2) -> 16.8 | G15: {=IF(E15=0,0,IF(E15=1,D15*$G$2,D15*$G$2*2))} -> 28 | H15: {=IF(E15>2,D15*(E15-2)*$H$2,0)} -> 11.2 | I15: =SUM(F15:H15) -> 56 | J15: B | K15: 19,4,19
A16: Úvod do strojového učení USU (10) | B16: 0 | C16: 28 | D16: 28 | E16: 0 | F16: =IF(B16=0,0*C16*$F$2,C16*$F$2) -> 0 | G16: {=IF(E16=0,0,IF(E16=1,D16*$G$2,D16*$G$2*2))} -> 0 | H16: {=IF(E16>2,D16*(E16-2)*$H$2,0)} -> 0 | I16: =SUM(F16:H16) -> 0 | J16: B
A17: FSB - Elektrot. a elektronika ELE (79) 1/2 MTI | B17: 104 | C17: 14 | D17: 14 | E17: 6 | F17: =IF(B17=0,0*C17*$F$2,C17*$F$2) -> 16.8 | G17: {=IF(E17=0,0,IF(E17=1,D17*$G$2,D17*$G$2*2))} -> 28 | H17: {=IF(E17>2,D17*(E17-2)*$H$2,0)} -> 44.8 | I17: =SUM(F17:H17) -> 89.6 | J17: B
A18: FSBKS - Elektrot. a elektr. ELE (9) 1/2 MTI | B18: 4 | C18: 7 | D18: 0 | E18: 1 | F18: =IF(B18=0,0*C18*$F$2,C18*$F$2) -> 8.4 | G18: {=IF(E18=0,0,IF(E18=1,D18*$G$2,D18*$G$2*2))} -> 0 | H18: {=IF(E18>2,D18*(E18-2)*$H$2,0)} -> 0 | I18: =SUM(F18:H18) -> 8.4 | J18: B | K18: Pozor, KS nejsou rozvrhovane časově
A19: III. ročník | I19: =SUM(I11:I18) -> 551.6
A20: Aplikace neuronových sítí ANS (8) | B20: 3 | C20: 28 | D20: 28 | E20: 1 | F20: =IF(B20=0,0*C20*$F$2,C20*$F$2) -> 33.6 | G20: {=IF(E20=0,0,IF(E20=1,D20*$G$2,D20*$G$2*2))} -> 28 | H20: {=IF(E20>2,D20*(E20-2)*$H$2,0)} -> 0 | I20: =SUM(F20:H20) -> 61.6 | J20: B
A21: Elektronická zařízení EZA (20) | B21: 37 | C21: 20 | D21: 20 | E21: 2 | F21: =IF(B21=0,0*C21*$F$2,C21*$F$2) -> 24 | G21: {=IF(E21=0,0,IF(E21=1,D21*$G$2,D21*$G$2*2))} -> 40 | H21: {=IF(E21>2,D21*(E21-2)*$H$2,0)} -> 0 | I21: =SUM(F21:H21) -> 64 | J21: B
A22: Modelování signálů a dat MSD (7) | B22: 3 | C22: 28 | D22: 28 | E22: 1 | F22: =IF(B22=0,0*C22*$F$2,C22*$F$2) -> 33.6 | G22: {=IF(E22=0,0,IF(E22=1,D22*$G$2,D22*$G$2*2))} -> 28 | H22: {=IF(E22>2,D22*(E22-2)*$H$2,0)} -> 0 | I22: =SUM(F22:H22) -> 61.6 | J22: B
A23: Multimediální technologie MT (20) | B23: 20 | C23: 28 | D23: 28 | E23: 2 | F23: =IF(B23=0,0*C23*$F$2,C23*$F$2) -> 33.6 | G23: {=IF(E23=0,0,IF(E23=1,D23*$G$2,D23*$G$2*2))} -> 56 | H23: {=IF(E23>2,D23*(E23-2)*$H$2,0)} -> 0 | I23: =SUM(F23:H23) -> 89.6 | J23: B
A24: Metody vytěžování dat MVD (7) | B24: 2 | C24: 28 | D24: 28 | E24: 1 | F24: =IF(B24=0,0*C24*$F$2,C24*$F$2) -> 33.6 | G24: {=IF(E24=0,0,IF(E24=1,D24*$G$2,D24*$G$2*2))} -> 28 | H24: {=IF(E24>2,D24*(E24-2)*$H$2,0)} -> 0 | I24: =SUM(F24:H24) -> 61.6 | J24: B
A25: Programovatelné obvody PO (2) | B25: 1 | C25: 28 | D25: 28 | E25: 1 | F25: =IF(B25=0,0*C25*$F$2,C25*$F$2) -> 33.6 | G25: {=IF(E25=0,0,IF(E25=1,D25*$G$2,D25*$G$2*2))} -> 28 | H25: {=IF(E25>2,D25*(E25-2)*$H$2,0)} -> 0 | I25: =SUM(F25:H25) -> 61.6 | J25: B
A26: Programovatelné obvody POB (21) | B26: 38 | C26: 20 | D26: 20 | E26: 3 | F26: =IF(B26=0,0*C26*$F$2,C26*$F$2) -> 24 | G26: {=IF(E26=0,0,IF(E26=1,D26*$G$2,D26*$G$2*2))} -> 40 | H26: {=IF(E26>2,D26*(E26-2)*$H$2,0)} -> 16 | I26: =SUM(F26:H26) -> 80 | J26: B
A27: Technologie pro big data TPB (16) | B27: 23 | C27: 28 | D27: 28 | E27: 1 | F27: =IF(B27=0,0*C27*$F$2,C27*$F$2) -> 33.6 | G27: {=IF(E27=0,0,IF(E27=1,D27*$G$2,D27*$G$2*2))} -> 28 | H27: {=IF(E27>2,D27*(E27-2)*$H$2,0)} -> 0 | I27: =SUM(F27:H27) -> 61.6 | J27: B
A28: Úvod do strojového učení USU (10) | B28: 0 | C28: 20 | D28: 20 | E28: 0 | F28: =IF(B28=0,0*C28*$F$2,C28*$F$2) -> 0 | G28: {=IF(E28=0,0,IF(E28=1,D28*$G$2,D28*$G$2*2))} -> 0 | H28: {=IF(E28>2,D28*(E28-2)*$H$2,0)} -> 0 | I28: =SUM(F28:H28) -> 0 | J28: B
A29: Úvod do zpracování obrazů UZO (21) | B29: 38 | C29: 20 | D29: 20 | E29: 2 | F29: =IF(B29=0,0*C29*$F$2,C29*$F$2) -> 24 | G29: {=IF(E29=0,0,IF(E29=1,D29*$G$2,D29*$G$2*2))} -> 40 | H29: {=IF(E29>2,D29*(E29-2)*$H$2,0)} -> 0 | I29: =SUM(F29:H29) -> 64 | J29: B
A30: FZS - Elektronika ELM*Z (21) | B30: 7 | C30: 28 | D30: 56 | E30: 1 | F30: =IF(B30=0,0*C30*$F$2,C30*$F$2) -> 33.6 | G30: {=IF(E30=0,0,IF(E30=1,D30*$G$2,D30*$G$2*2))} -> 56 | H30: {=IF(E30>2,D30*(E30-2)*$H$2,0)} -> 0 | I30: =SUM(F30:H30) -> 89.6 | J30: B
A31: Bakalářský seminář BS (38) | B31: 44 | C31: 0 | D31: 20 | E31: 3 | F31: =IF(B31=0,0*C31*$F$2,C31*$F$2) -> 0 | G31: {=IF(E31=0,0,IF(E31=1,D31*$G$2,D31*$G$2*2))} -> 40 | H31: {=IF(E31>2,D31*(E31-2)*$H$2,0)} -> 16 | I31: =SUM(F31:H31) -> 56 | J31: B
... A33: Nástroje Office NOF (0) | B33: 2 | C33: 20 | D33: 20 | E33: 1 | F33: =IF(B33=0,0*C33*$F$2,C33*$F$2) -> 24 | G33: {=IF(E33=0,0,IF(E33=1,D33*$G$2,D33*$G$2*2))} -> 20 | H33: {=IF(E33>2,D33*(E33-2)*$H$2,0)} -> 0 | I33: =SUM(F33:H33) -> 44 | J33: B
A34: Počítačová grafika 2 PG2 (10) | B34: 21 | C34: 20 | D34: 20 | E34: 2 | F34: =IF(B34=0,0*C34*$F$2,C34*$F$2) -> 24 | G34: {=IF(E34=0,0,IF(E34=1,D34*$G$2,D34*$G$2*2))} -> 40 | H34: {=IF(E34>2,D34*(E34-2)*$H$2,0)} -> 0 | I34: =SUM(F34:H34) -> 64 | J34: B | K34: 18.3
A35: Úvod do zpracování obrazů UZO (19) | B35: 38 | C35: 20 | D35: 20 | E35: 2 | F35: =IF(B35=0,0*C35*$F$2,C35*$F$2) -> 24 | G35: {=IF(E35=0,0,IF(E35=1,D35*$G$2,D35*$G$2*2))} -> 40 | H35: {=IF(E35>2,D35*(E35-2)*$H$2,0)} -> 0 | I35: =SUM(F35:H35) -> 64 | J35: B
A36: FZS - Snímání, digit. a zpr. dat DZD*Z (21) | B36: 9 | C36: 14 | D36: 14 | E36: 1 | F36: =IF(B36=0,0*C36*$F$2,C36*$F$2) -> 16.8 | G36: {=IF(E36=0,0,IF(E36=1,D36*$G$2,D36*$G$2*2))} -> 14 | H36: {=IF(E36>2,D36*(E36-2)*$H$2,0)} -> 0 | I36: =SUM(F36:H36) -> 30.8 | J36: B | K36: 5.4
I37: =SUM(I20:I36) -> 1018
A38: IV. ročník | H38: Výuka BS: | I38: =SUM(I37,I19,I10) -> 1888.8
A39: FZS - Vybrané kap. z teorie signálu KSA (9) | B39: 9 | C39: 28 | D39: 28 | E39: 1 | F39: =IF(B39=0,0*C39*$F$2,C39*$F$2) -> 33.6 | G39: {=IF(E39=0,0,IF(E39=1,D39*$G$3,D39*$G$3*2))} -> 28 | H39: {=IF(E39>2,D39*(E39-2)*$H$3,0)} -> 0 | I39: =SUM(F39:H39) -> 61.6 | J39: N
A40: FZS - Počítačové zpr. signálů PZS*Z (9) | B40: 9 | C40: 28 | D40: 28 | E40: 1 | F40: =IF(B40=0,0*C40*$F$2,C40*$F$2) -> 33.6 | G40: {=IF(E40=0,0,IF(E40=1,D40*$G$3,D40*$G$3*2))} -> 28 | H40: {=IF(E40>2,D40*(E40-2)*$H$3,0)} -> 0 | I40: =SUM(F40:H40) -> 61.6 | J40: N
A41: FZS - Technická dok., řízení proj. TDO (8) | B41: 9 | C41: 14 | D41: 14 | E41: 1 | F41: =IF(B41=0,0*C41*$F$2,C41*$F$2) -> 16.8 | G41: {=IF(E41=0,0,IF(E41=1,D41*$G$3,D41*$G$3*2))} -> 14 | H41: {=IF(E41>2,D41*(E41-2)*$H$3,0)} -> 0 | I41: =SUM(F41:H41) -> 30.8 | J41: N
A42: Digitální audio inženýrství DAI (5) | B42: 4 | C42: 28 | D42: 28 | E42: 1 | F42: =IF(B42=0,0*C42*$F$2,C42*$F$2) -> 33.6 | G42: {=IF(E42=0,0,IF(E42=1,D42*$G$3,D42*$G$3*2))} -> 28 | H42: {=IF(E42>2,D42*(E42-2)*$H$3,0)} -> 0 | I42: =SUM(F42:H42) -> 61.6 | J42: N
...

Sheet 6_Garanti
A1: old | B1: Typ studijního programu | C1: Kód a název studijního programu | D1: Studijní obor | E1: Garant SO | F1: Forma | G1: SDS | H1: Datum získání akreditace | I1: Platnost akreditace do | J1: Garant studijního programu | K1: KAT | L1: poč | M1: A/N | N1: částka | O1: kontrola | P1: opačná kontrola
A2: N | B2: Bakalářský | C2: B0588A110003 Aplikované vědy v inženýrství | F2: P | G2: 3 roky | H2: 44120 | I2: 47772 | J2: doc. Mgr. Jan Stebel, Ph.D. | K2: NTI | L2: =COUNTIF($J$2:$J$39,J2) -> 1 | M2: A | N2: =IF(M2="A",2000,0) -> 2000 | O2: =IF(SUMIF($J$2:$J$35,J2,$N$2:$N$35)=0,"!!","") | P2: =SUMIF($J$2:$J$36,J2,$N$2:$N$36) -> 2000
A3: N | B3: Bakalářský | C3: B0613A140005 Informační technologie | F3: P | G3: 3 roky | H3: 43328 | I3: 46981 | J3: doc. Ing. Josef Chaloupka, Ph.D. | K3: ITE | L3: =COUNTIF($J$2:$J$35,J3) -> 2 | M3: A | N3: =IF(M3="A",2000,0) -> 2000 | O3: =IF(SUMIF($J$2:$J$35,J3,$N$2:$N$35)=0,"!!","") | P3: =SUMIF($J$2:$J$36,J3,$N$2:$N$36) -> 2000
A4: N | B4: Bakalářský | C4: B0714A270001 Mechatronika | F4: P | G4: 3 roky | H4: 43328 | I4: 46981 | J4: doc. Ing. Josef Černohorský, Ph.D. | K4: MTI | L4: =COUNTIF($J$2:$J$35,J4) -> 1 | M4: A | N4: =IF(M4="A",2000,0) -> 2000 | O4: =IF(SUMIF($J$2:$J$35,J4,$N$2:$N$35)=0,"!!","") | P4: =SUMIF($J$2:$J$36,J4,$N$2:$N$36) -> 2000
A5: N | B5: Bakalářský | C5: B0719A130001 Nanotechnologie | F5: P | G5: 3 roky | H5: 43386 | I5: 47039 | J5: prof. Ing. Josef Šedlbauer, Ph.D. | K5: KCH | L5: =COUNTIF($J$2:$J$35,J5) -> 3 | M5: A | N5: =IF(M5="A",2000,0) -> 2000 | O5: =IF(SUMIF($J$2:$J$35,J5,$N$2:$N$35)=0,"!!","") | P5: =SUMIF($J$2:$J$36,J5,$N$2:$N$36) -> 2000
A6: N | B6: Navazující magisterský | C6: N0588A110001 Aplikované vědy v inženýrství | F6: P | G6: 2 roky | H6: 44120 | I6: 47772 | J6: doc. Ing. Petr Šidlof, Ph.D. | K6: NTI | L6: =COUNTIF($J$2:$J$35,J6) -> 5 | M6: A | N6: =IF(M6="A",2000,0) -> 2000 | O6: =IF(SUMIF($J$2:$J$35,J6,$N$2:$N$35)=0,"!!","") | P6: =SUMIF($J$2:$J$36,J6,$N$2:$N$36) -> 2000
A7: N | B7: Navazující magisterský | C7: N0613A140028 Informační technologie | F7: P | G7: 2 roky | H7: 44049 | I7: 45875 | J7: doc. RNDr. Pavel Satrapa, Ph.D. | K7: NTI | L7: =COUNTIF($J$2:$J$35,J7) -> 3 | M7: A | N7: =IF(M7="A",2000,0) -> 2000 | O7: =IF(SUMIF($J$2:$J$35,J7,$N$2:$N$35)=0,"!!","") | P7: =SUMIF($J$2:$J$36,J7,$N$2:$N$36) -> 2000
A8: N | B8: Navazující magisterský | C8: N0613A140029 Information Technology | F8: P | G8: 2 roky | H8: 44049 | I8: 45875 | J8: doc. RNDr. Pavel Satrapa, Ph.D. | K8: NTI | L8: =COUNTIF($J$2:$J$35,J8) -> 3 | M8: N | N8: =IF(M8="A",2000,0) -> 0 | O8: =IF(SUMIF($J$2:$J$35,J8,$N$2:$N$35)=0,"!!","") | P8: =SUMIF($J$2:$J$36,J8,$N$2:$N$36) -> 2000
A9: N | B9: Navazující magisterský | C9: N0714A270010 Mechatronika | F9: P | G9: 2 roky | H9: 44028 | I9: 47680 | J9: doc. Dr. Mgr. Ing. Jaroslav Hlava | K9: MTI | L9: =COUNTIF($J$2:$J$35,J9) -> 5 | M9: A | N9: =IF(M9="A",2000,0) -> 2000 | O9: =IF(SUMIF($J$2:$J$35,J9,$N$2:$N$35)=0,"!!","") | P9: =SUMIF($J$2:$J$36,J9,$N$2:$N$36) -> 2000
A10: N | B10: Navazující magisterský | C10: N0714A150003 Mechatronics | F10: P | G10: 2 roky | H10: 43462 | I10: 47115 | J10: doc. Dr. Mgr. Ing. Jaroslav Hlava | K10: MTI | L10: =COUNTIF($J$2:$J$35,J10) -> 5 | M10: N | N10: =IF(M10="A",2000,0) -> 0 | O10: =IF(SUMIF($J$2:$J$35,J10,$N$2:$N$35)=0,"!!","") | P10: =SUMIF($J$2:$J$36,J10,$N$2:$N$36) -> 2000
A11: N | B11: Navazující magisterský | C11: N0719A270001 Nanotechnologie | F11: P | G11: 2 roky | H11: 43386 | I11: 47039 | J11: prof. Ing. Josef Šedlbauer, Ph.D. | K11: KCH | L11: =COUNTIF($J$2:$J$35,J11) -> 3 | M11: N | N11: =IF(M11="A",2000,0) -> 0 | O11: =IF(SUMIF($J$2:$J$35,J11,$N$2:$N$35)=0,"!!","") | P11: =SUMIF($J$2:$J$36,J11,$N$2:$N$36) -> 2000
A12: N | B12: Doktorský | C12: P0788D270007 Aplikované vědy v inženýrství | F12: P, K | G12: 4 roky | H12: 43963 | I12: 47615 | J12: doc. Ing. Petr Šidlof, Ph.D. | K12: NTI | L12: =COUNTIF($J$2:$J$35,J12) -> 5 | M12: N | N12: =IF(M12="A",2000,0) -> 0 | O12: =IF(SUMIF($J$2:$J$35,J12,$N$2:$N$35)=0,"!!","") | P12: =SUMIF($J$2:$J$36,J12,$N$2:$N$36) -> 2000
A13: N | B13: Doktorský | C13: P0788D270006 Applied Sciences in Engineering | F13: P, K | G13: 4 roky | H13: 43963 | I13: 47615 | J13: doc. Ing. Petr Šidlof, Ph.D. | K13: NTI | L13: =COUNTIF($J$2:$J$35,J13) -> 5 | M13: N | N13: =IF(M13="A",2000,0) -> 0 | O13: =IF(SUMIF($J$2:$J$35,J13,$N$2:$N$35)=0,"!!","") | P13: =SUMIF($J$2:$J$36,J13,$N$2:$N$36) -> 2000
A14: N | B14: Doktorský | C14: P0714D150008 Technická kybernetika | F14: P, K | G14: 4 roky | H14: 43690 | I14: 47343 | J14: prof. Ing. Zbyněk Koldovský, Ph.D. | K14: ITE | L14: =COUNTIF($J$2:$J$35,J14) -> 3 | M14: A | N14: =IF(M14="A",2000,0) -> 2000 | O14: =IF(SUMIF($J$2:$J$35,J14,$N$2:$N$35)=0,"!!","") | P14: =SUMIF($J$2:$J$36,J14,$N$2:$N$36) -> 2000
... A17: N | B17: Doktorský | C17: P0588D130006 Environmentální inženýrství | F17: P, K | G17: 4 roky | H17: 44243 | I17: 46085 | J17: doc. Ing. Jan Šembera, Ph.D. | K17: NTI | L17: =COUNTIF($J$2:$J$35,J17) -> 3 | M17: N | N17: =IF(M17="A",2000,0) -> 0 | O17: =IF(SUMIF($J$2:$J$35,J17,$N$2:$N$35)=0,"!!","") | P17: =SUMIF($J$2:$J$36,J17,$N$2:$N$36) -> 2000
P18: =SUMIF($J$2:$J$36,J18,$N$2:$N$36) -> 0
C19: Staré akreditace | P19: =SUMIF($J$2:$J$36,J19,$N$2:$N$36) -> 0
A20: S | B20: Bakalářský | C20: B2612 Elektrotechnika a informatika | D20: 2612R011 Elektronické informační a řídicí systémy | E20: doc. Ing. Libor Tůma, CSc. | F20: P, K | G20: 3 roky | I20: 45657 | J20: doc. Ing. Libor Tůma, CSc. | K20: MTI | L20: =COUNTIF($J$2:$J$35,J20) -> 1 | M20: A | N20: =IF(M20="A",2000,0) -> 2000 | O20: =IF(SUMIF($J$2:$J$35,J20,$N$2:$N$35)=0,"!!","") | P20: =SUMIF($J$2:$J$36,J20,$N$2:$N$36) -> 2000
A21: S | B21: Bakalářský | C21: B2612 Elektrotechnika a informatika | D21: 1802R022 Informatika a logistika | E21: prof. Ing. Zdeněk Plíva, Ph.D. | F21: P, K | G21: 3 roky | I21: 45657 | J21: prof. Ing. Zdeněk Plíva, Ph.D. | K21: ITE | L21: =COUNTIF($J$2:$J$35,J21) -> 1 | M21: X | N21: =IF(M21="A",2000,0) -> 0 | O21: =IF(SUMIF($J$2:$J$35,J21,$N$2:$N$35)=0,"!!","") -> !! | P21: =SUMIF($J$2:$J$36,J21,$N$2:$N$36) -> 0
A22: S | B22: Bakalářský | C22: B2646 Informační technologie | D22: 1802R007 Informační technologie | E22: doc. Ing. Josef Chaloupka, Ph.D. | F22: P | G22: 3 roky | I22: 45657 | J22: doc. Ing. Josef Chaloupka, Ph.D. | K22: ITE | L22: =COUNTIF($J$2:$J$35,J22) -> 2 | M22: N | N22: =IF(M22="A",2000,0) -> 0 | O22: =IF(SUMIF($J$2:$J$35,J22,$N$2:$N$35)=0,"!!","") | P22: =SUMIF($J$2:$J$36,J22,$N$2:$N$36) -> 2000
A23: S | B23: Bakalářský | C23: B3942 Nanotechnologie | D23: 3942R002 Nanomateriály | E23: prof. Ing. Josef Šedlbauer, Ph.D. | F23: P | G23: 3 roky | I23: 45657 | J23: prof. Ing. Josef Šedlbauer, Ph.D. | K23: KCH | L23: =COUNTIF($J$2:$J$35,J23) -> 3 | M23: N | N23: =IF(M23="A",2000,0) -> 0 | O23: =IF(SUMIF($J$2:$J$35,J23,$N$2:$N$35)=0,"!!","") | P23: =SUMIF($J$2:$J$36,J23,$N$2:$N$36) -> 2000
A24: S | B24: Bakalářský | C24: B3901 Aplikované vědy v inženýrství | D24: 3901R055 Aplikované vědy v inženýrství | E24: doc. Ing. Petr Šidlof, Ph.D. | F24: P | G24: 3 roky | I24: 45657 | J24: doc. Ing. Petr Šidlof, Ph.D. | K24: NTI | L24: =COUNTIF($J$2:$J$35,J24) -> 5 | M24: N | N24: =IF(M24="A",2000,0) -> 0 | O24: =IF(SUMIF($J$2:$J$35,J24,$N$2:$N$35)=0,"!!","") | P24: =SUMIF($J$2:$J$36,J24,$N$2:$N$36) -> 2000
A25: S | B25: Navazující magisterský | C25: N2612 Elektrotechnika a informatika | D25: 3902T005 Automatické řízení a inženýrská informatika | E25: doc. Dr. Mgr. Ing. Jaroslav Hlava | F25: P | G25: 2 roky | I25: 45657 | J25: doc. Dr. Mgr. Ing. Jaroslav Hlava | K25: MTI | L25: =COUNTIF($J$2:$J$35,J25) -> 5 | M25: N | N25: =IF(M25="A",2000,0) -> 0 | O25: =IF(SUMIF($J$2:$J$35,J25,$N$2:$N$35)=0,"!!","") | P25: =SUMIF($J$2:$J$36,J25,$N$2:$N$36) -> 2000
A26: S | B26: Navazující magisterský | C26: N2612 Elektrotechnika a informatika | D26: 3906T001 Mechatronika | E26: doc. Dr. Mgr. Ing. Jaroslav Hlava | F26: P | G26: 2 roky | I26: 45657 | J26: doc. Dr. Mgr. Ing. Jaroslav Hlava | K26: MTI | L26: =COUNTIF($J$2:$J$35,J26) -> 5 | M26: N | N26: =IF(M26="A",2000,0) -> 0 | O26: =IF(SUMIF($J$2:$J$35,J26,$N$2:$N$35)=0,"!!","") | P26: =SUMIF($J$2:$J$36,J26,$N$2:$N$36) -> 2000
A27: S | B27: Navazující magisterský | C27: N2612 Elektrotechnika a informatika | D27: 1802T007 Informační technologie | E27: doc. RNDr. Pavel Satrapa, Ph.D. | F27: P | G27: 2 roky | I27: 45657 | J27: doc. RNDr. Pavel Satrapa, Ph.D. | K27: NTI | L27: =COUNTIF($J$2:$J$35,J27) -> 3 | M27: N | N27: =IF(M27="A",2000,0) -> 0 | O27: =IF(SUMIF($J$2:$J$35,J27,$N$2:$N$35)=0,"!!","") | P27: =SUMIF($J$2:$J$36,J27,$N$2:$N$36) -> 2000
A28: S | B28: Navazující magisterský | C28: N2612 Electrical Engineering and Informatics | D28: 3906T001 Mechatronics | E28: doc. Dr. Mgr. Ing. Jaroslav Hlava | F28: P | G28: 2 roky | I28: 45657 | J28: doc. Dr. Mgr. Ing. Jaroslav Hlava | K28: MTI | L28: =COUNTIF($J$2:$J$35,J28) -> 5 | M28: N | N28: =IF(M28="A",2000,0) -> 0 | O28: =IF(SUMIF($J$2:$J$35,J28,$N$2:$N$35)=0,"!!","") | P28: =SUMIF($J$2:$J$36,J28,$N$2:$N$36) -> 2000
A29: S | B29: Navazující magisterský | C29: N2612 Electrical Engineering and Informatics | D29: 2612T071 Engineering of Interactive Systems | E29: prof. Ing. Jaroslav Nosek, CSc. | F29: P | G29: 2 roky | I29: 45657 | J29: prof. Ing. Jaroslav Nosek, CSc. | K29: MTI | L29: =COUNTIF($J$2:$J$35,J29) -> 1 | M29: X | N29: =IF(M29="A",2000,0) -> 0 | O29: =IF(SUMIF($J$2:$J$35,J29,$N$2:$N$35)=0,"!!","") -> !! | P29: =SUMIF($J$2:$J$36,J29,$N$2:$N$36) -> 0
A30: S | B30: Navazující magisterský | C30: N3942 Nanotechnologie | D30: 3942T002 Nanomateriály | E30: prof. Dr. Ing. Miroslav Černík, CSc. | F30: P | G30: 2 roky | I30: 45657 | J30: prof. Dr. Ing. Miroslav Černík, CSc. | K30: NTI | L30: =COUNTIF($J$2:$J$35,J30) -> 2 | M30: A | N30: =IF(M30="A",2000,0) -> 2000 | O30: =IF(SUMIF($J$2:$J$35,J30,$N$2:$N$35)=0,"!!","") | P30: =SUMIF($J$2:$J$36,J30,$N$2:$N$36) -> 2000
A31: S | B31: Navazující magisterský | C31: N3901 Aplikované vědy v inženýrství | D31: 3901T055 Aplikované vědy v inženýrství | E31: doc. Ing. Petr Šidlof, Ph.D. | F31: P | G31: 2 roky | I31: 45657 | J31: doc. Ing. Petr Šidlof, Ph.D. | K31: NTI | L31: =COUNTIF($J$2:$J$35,J31) -> 5 | M31: N | N31: =IF(M31="A",2000,0) -> 0 | O31: =IF(SUMIF($J$2:$J$35,J31,$N$2:$N$35)=0,"!!","") | P31: =SUMIF($J$2:$J$36,J31,$N$2:$N$36) -> 2000
... A35: S | B35: Doktorský | C35: P3942 Nanotechnologie | D35: 3942V001 Nanotechnologie | E35: prof. Dr. Ing. Miroslav Černík, CSc. | F35: P, K | G35: 4 roky | I35: 45657 | J35: prof. Dr. Ing. Miroslav Černík, CSc. | K35: NTI | L35: =COUNTIF($J$2:$J$35,J35) -> 2 | M35: N | N35: =IF(M35="A",2000,0) -> 0 | O35: =IF(SUMIF($J$2:$J$35,J35,$N$2:$N$35)=0,"!!","") | P35: =SUMIF($J$2:$J$36,J35,$N$2:$N$36) -> 2000
O36: =IF(SUMIF($J$2:$J$35,J16,$N$2:$N$35)=0,"!!","")
O37: =IF(SUMIF($J$2:$J$35,J17,$N$2:$N$35)=0,"!!","")
C40: Poznámky: | O40: Vracet na ústav? ANO/NE | P40: pokud NE, vyplácí přímo DFM
C41: VMP TUL - Příloha č. 3 -> Příplatky za vedení a výkon funkce = 2.000,- Kč | N41: Celkem | O41: NE
C42: -> zaměstnanec garantující alespoň jeden studijní program (platnost po dobu platnosti akreditace daného SP) | K42: ITE | N42: =SUMIF($K$2:$K$36,K42,$N$2:$N$36) -> 4000 | O42: =IF($O$41="ANO",N42*12*1.338,0) -> 0
C43: -> příplatek uveden do Návrhu na pracovní a mzdové zařazaní + zadán do GaP, hrazeno se SFM činností 107 (7117/107) | K43: MTI | N43: =SUMIF($K$2:$K$36,K43,$N$2:$N$36) -> 6000 | O43: =IF($O$41="ANO",N43*12*1.338,0) -> 0
C44: kontrolu úplnosti uvedených studijních programů - děkan | K44: NTI | N44: =SUMIF($K$2:$K$36,K44,$N$2:$N$36) -> 12000 | O44: =IF($O$41="ANO",N44*12*1.338,0) -> 0
C45: kontrolu vložení dat do návrhů a systému GaP, ověření úplnosti SP- tajemnice | K45: KCH | N45: =SUMIF($K$2:$K$36,K45,$N$2:$N$36) -> 2000 | O45: =IF($O$41="ANO",N45*12*1.338,0) -> 0
C46: nová akreditace - vložení dat - děkan/tajemnice | N46: =SUM(N42:N45)*12 -> 288000 | O46: =IF(O41="NE",N46*1.338,O45) -> 385344
C47: doba trvání nastavení příplatku je dle délky platnosti akreditace
...

Sheet 7_Plochy pracovišť
A1: areál | B1: budova | C1: podlaží | D1: název místnosti | E1: plocha | F1: zařazení | G1: účel | H1: útvar
A2: 1 | B2: A | C2: -1 | D2: ITE - laboratoř PCB 4 | E2: 16.2 | F2: 1 | G2: 1 | H2: 7625
A3: 1 | B3: A | C3: -1 | D3: ITE - laboratoř PVB 3 | E3: 11.5 | F3: 1 | G3: 1 | H3: 7625
A4: 1 | B4: A | C4: -1 | D4: NTI - laboratoř | E4: 17.8 | F4: 1 | G4: 1 | H4: 7640
A5: 1 | B5: A | C5: -1 | D5: NTI - laboratoř | E5: 41.9 | F5: 1 | G5: 1 | H5: 7640
A6: 1 | B6: A | C6: -1 | D6: MTI - dílna | E6: 3.7 | F6: 1 | G6: 1 | H6: 7635
A7: 1 | B7: A | C7: -1 | D7: MTI - dílna | E7: 9.6 | F7: 1 | G7: 1 | H7: 7635
A8: 1 | B8: A | C8: -1 | D8: MTI - šatna | E8: 13.9 | F8: 1 | G8: 1 | H8: 7635
A9: 1 | B9: A | C9: -1 | D9: MTI-pracovna pedagoga | E9: 10.7 | F9: 1 | G9: 1 | H9: 7635
A10: 1 | B10: A | C10: -1 | D10: MTI - laboratoř A001 | E10: 118.7 | F10: 1 | G10: 1 | H10: 7630
A11: 1 | B11: A | C11: -1 | D11: MTI - laboratoř A002 | E11: 53.4 | F11: 1 | G11: 1 | H11: 7630
A12: 1 | B12: A | C12: -1 | D12: MTI - laboratoř A003 | E12: 34.75 | F12: 1 | G12: 1 | H12: 7630
A13: 1 | B13: A | C13: 1 | D13: NTI - laboratoř | E13: 30.6 | F13: 1 | G13: 1 | H13: 7640
... A137: 3 | B137: SK | C137: 1 | D137: Sklad | E137: 18 | F137: 1 | G137: 2 | H137: 7635
E138: =SUM(E2:E137) -> 3861.7 | F138: Celá FM
C140: Zdroj: Pasporty24.xls
A141: Výpočet 20% FRIM (plochy s kódem účelu=1 a 5 a zařazením 1 započítává se PUČ)
D143: CELKEM | E143: kanceláře/pracovny | F143: laboratoře/učebny | G143: ostatní ** | H143: pozn. OSTATNÍ
C144: 7620 | D144: =SUM(E144:G144) -> 239.19 | E144: 99.25 | F144: 139.94 | G144: 0 | H144: provozní, zasedací mistnost
C145: 7625 | D145: =SUM(E145:G145) -> 332.43 | E145: 273.88 | F145: 27.7 | G145: 30.85 | H145: šatna, sklad,dílna
C146: 7630 | D146: =SUM(E146:G146) -> 1166.56 | E146: 133.05 | F146: 1014.12 | G146: 19.39
C147: 7635 | D147: =SUM(E147:G147) -> 1025.18 | E147: 788.46 | F147: 128.16 | G147: 108.56
C148: 7640 | D148: =SUM(E148:G148) -> 499.59 | E148: 60.85 | F148: 438.74 | G148: 0
C149: 7645 | D149: =SUM(E149:G149) -> 412.35 | E149: 359.79 | F149: 23.47 | G149: 29.09
C150: 7817 | D150: =SUM(E150:G150) -> 151.78 | E150: 75.58 | F150: 0 | G150: 76.2
C151: 7117 | D151: =SUM(E151:G151) -> 34.62 | E151: 34.62 | F151: 0 | G151: 0
D152: =SUM(D144:D151) -> 3861.7 | E152: =SUM(E144:E151) -> 1825.48 | F152: =SUM(F144:F151) -> 1772.13 | G152: =SUM(G144:G151) -> 264.09
B153: 3861.7 | C153: PUČ na 2024 | D153: =D152-E138 -> 0 | G153: =SUM(E152:G152) -> 3861.7
C155: ITE | D155: =D144+D145 -> 571.62
C156: MTI | D156: =D146+D147 -> 2191.74
C157: NTI | D157: =D148+D149 -> 911.94
C158: DFM+SFM | D158: =D150+D151 -> 186.4
D159: =SUM(D155:D158) -> 3861.7

Sheet 8_Výpočet_20%_FRIM
A1: Výpočet podílů na úhradě 20% FRIM (stanoveno podle poměru užívaných ploch)
C3: Podíl na tvorbě FRIMu (20%)
B4: FM | C4: 3861.7 | D4: zaokrouhleno
B5: DFM | C5: =$C$4*E18 -> 186.4 | D5: =CEILING(C18,1)-1 -> 23000
B6: ITE | C6: =$C$4*E19 -> 571.62 | D6: =CEILING(C19,1) -> 70534
B7: MTI | C7: =$C$4*E20 -> 2191.74 | D7: =CEILING(C20,1) -> 270445
B8: NTI | C8: =$C$4*E21 -> 911.94 | D8: =CEILING(C21,1) -> 112527
B9: Celkem | C9: =C5+C6+C7+C8 -> 3861.7 | D9: =SUM(D5:D8) -> 476506
C10: =D22 -> 3861.7 | D10: PUČ FM
B12: Plochy FM (Pasporty24 - K:\Rozpocet\Rok2024\Vypocet)
A14: Návrh rozpočtu určuje podíl na úhradě 20 % FRIMu stanovený podle poměru užívaných ploch
B16: 2024 | C16: Podíl na tvorbě FRIMu (20%) | D16: plochy pracovišť | E16: % vyjádření užitné plochy
B17: FM celkem | C17: ='0_PRIDEL'!H26 -> 476505.68 | D17: ='0_PRIDEL'!H25 -> 3861.7 | E17: 1
B18: DFM | C18: =E18*$C$17 -> 23000.404 | D18: ='7_Plochy pracovišť'!D158 -> 186.4 | E18: =D18/$D$17 -> 0.048268897
B19: ITE | C19: =E19*$C$17 -> 70533.748 | D19: ='7_Plochy pracovišť'!D155 -> 571.62 | E19: =D19/$D$17 -> 0.14802289
B20: MTI | C20: =E20*$C$17 -> 270444.77 | D20: ='7_Plochy pracovišť'!D156 -> 2191.74 | E20: =D20/$D$17 -> 0.56755833
B21: NTI | C21: =E21*$C$17 -> 112526.76 | D21: ='7_Plochy pracovišť'!D157 -> 911.94 | E21: =D21/$D$17 -> 0.23614988
B22: Celkem | C22: =SUM(C18:C21) -> 476505.68 | D22: =SUM(D18:D21) -> 3861.7 | E22: =SUM(E18:E21) -> 1
C24: KVE PUČ 2024: | D24: =D17-D22 -> 0

Sheet 9_DFM
A1: Rozpočet FM na rok 2024 - DFM, činnost 106
B4: 2024
A5: příděl 106 na DFM+SFM : | B5: 3800000 | C5: ***
A6: HM děk., proděk.,… | B6: =C16 -> 3004018 | C6: =#REF!*C11*1.34*0 -> #REF!
A7: korekce rozpočtu | C7: (např. plánované výdaje navíc)
A8: výpočet CELKEM | B8: =B6+B5+B7 -> 6804018
A9: kontrola přidělení | B9: =B6-C16 -> 0
A11: Přehled plánovatelných (mzdových) výdajů DFM | B11: počet měsíců
B12: na pracoviště | F12: 2024 - mzdové náklady zaměstanců, kteří nejsou kmenovými pracovníky FM, ale podílejí se na vedení FM
B13: ITE | C13: =SUMIF($R$15:$R$25,B13,$Q$15:$Q$25)*1.338 -> 0 | D13: ="mzdové náklady převedené "&B13&" (viz list 10/sl.K)" -> mzdové náklady převedené ITE (viz list 10/sl.K) | F13: Tabulka mzdových prostředků platba z DFM / SFM
B14: MTI | C14: =SUMIF($R$15:$R$25,B14,$Q$15:$Q$25)*1.338 -> 0 | D14: ="mzdové náklady převedené "&B14&" (viz list 10/sl.K)" -> mzdové náklady převedené MTI (viz list 10/sl.K) | G14: TARIF | H14: VEDENÍ příplatek** | I14: OSOH příplatek/základní | J14: Doplatek do 50 % mimo DFM* | L14: počet měs. | M14: bez odvodů celkem | P14: počet měs. | Q14: Doplatek do 50 %
B15: NTI | C15: =SUMIF($R$15:$R$25,B15,$Q$15:$Q$25)*1.338+SUMIF($R$15:$R$25,B15,$Q$15:$Q$25)*0.01 -> 202200 | D15: ="mzdové náklady převedené "&B15&" (viz list 10/sl.K)" -> mzdové náklady převedené NTI (viz list 10/sl.K) | F15: Černohorský | G15: =(50000*0.3) -> 15000 | H15: 22000 | I15: 0 | K15: děkan | L15: 12 | M15: =SUM(G15:I15)*L15 -> 444000 | N15: DFM | P15: 0 | Q15: =J15*L15 -> 0 | R15: MTI
B16: DFM | C16: =SUMIF($N$15:$N$25,B16,$M$15:$M$25)*1.338+SUMIF($N$15:$N$25,B16,$M$15:$M$25)*0.01 -> 3004018 | D16: ="mzdové náklady rozpočtem "&B16&" mimo paušál > viz B6" -> mzdové náklady rozpočtem DFM mimo paušál > viz B6 | F16: Šidlof | G16: =50000*0.25 -> 12500 | H16: 10000 | I16: 0 | J16: =50000*0.25 -> 12500 | K16: proděkan | L16: 12 | M16: =SUM(G16:I16)*L16 -> 270000 | N16: DFM | P16: 12 | Q16: =J16*L16 -> 150000 | R16: NTI
F17: Plíva | G17: =55000*0.5 -> 27500 | H17: 10000 | I17: 0 | K17: proděkan | L17: 12 | M17: =(SUM(G17:I17)*L17)+5800 -> 455800 | N17: DFM | P17: 0 | Q17: =J17*P17 -> 0 | R17: ITE
F18: Koprnický | G18: =38000*0.5 -> 19000 | H18: 10000 | I18: 0 | K18: proděkan | L18: 12 | M18: =SUM(G18:I18)*L18 -> 348000 | N18: DFM | P18: 0 | Q18: =J18*L18 -> 0 | R18: MTI
F19: Vitvarová | G19: =38000*0.5 -> 19000 | H19: 10000 | I19: 0 | K19: proděkan | L19: 13 | M19: =SUM(G19:I19)*L19 -> 377000 | N19: DFM | P19: 0 | Q19: =J19*L19 -> 0 | R19: MTI
F20: Mrázková | G20: =30000*0.2 -> 6000 | H20: 0 | I20: 6000 | K20: Publikace, Metodika 17+ | L20: 12 | M20: =SUM(G20:I20)*L20 -> 144000 | N20: DFM | P20: 0 | Q20: =J20*L20 -> 0 | R20: REK
F21: Tůma | G21: =40000*0.1 -> 4000 | H21: 0 | I21: 1500 | K21: STAG | L21: 12 | M21: =SUM(G21:I21)*L21 -> 66000 | N21: DFM | P21: 0 | Q21: =J21*L21 -> 0 | R21: MTI
F22: Slavík | G22: =38000*0.05 -> 1900 | H22: 0 | I22: 0 | K22: propagace | L22: 12 | M22: =SUM(G22:I22)*L22 -> 22800 | N22: DFM | P22: 0 | Q22: =J22*L22 -> 0 | R22: MTI
F23: Jeníček | G23: =37000*0.05 -> 1850 | H23: 0 | I23: 1850 | K23: IT správa | L23: 12 | M23: =SUM(G23:I23)*L23 -> 44400 | N23: DFM | P23: 0 | Q23: =J23*L23 -> 0 | R23: ITE
F24: Severýn | G24: 0 | H24: 0 | I24: 3500 | K24: AS FM | L24: 12 | M24: =SUM(G24:I24)*L24 -> 42000 | N24: DFM | P24: 0 | Q24: =J24*L24 -> 0 | R24: NTI
F25: Hernych | G25: =29000*0.25 -> 7250 | I25: 7250 | K25: DOD | L25: 1 | M25: =SUM(G25:I25)*L25 -> 14500 | N25: DFM | P25: 0 | Q25: =J25*L25 -> 0 | R25: MTI
F27: * DOPLATEK DO 50 % -> vráceno rozpočtovou úpravou zpět na ústav do činnosti 106
F28: ** proděkan příplatek = 10.000 Kč
F29: ***FIX - mzdové náklady kmenových pracovníků, provozní náklady od roku 2019 = 3,8 MKč

Sheet 10_Celkem_106
A1: Rozpočet FM na rok 2024 - činn. 106
B3: Příděl 106 na FM | D3: ='0_PRIDEL'!B19 -> 47020030
B4: odebráno na podporu Doc/Prof (4) | C4: ='4_DOC_PROF'!I15 -> 60000 | D4: =D3-C4 -> 46960030
B5: odebráno na kvalif.strukturu (4a) | C5: ='4a_úvazky-na-FM'!G27 -> 512642.63 | D5: =D4-C5 -> 46447388
B6: nevyplatitelní proděkani (9) | C6: =SUM('9_DFM'!C13:C15) -> 202200 | D6: =D5-C6 -> 46245188
B7: Garanti (6) | C7: ='6_Garanti'!O46 -> 385344 | D7: =D6-C7 -> 45859844 | E7: //'6_Garanti'!O38
B9: sl. B | C9: sl. C | D9: sl. D | E9: sl. E | F9: sl. F | G9: sl. G | H9: sl. H | I9: sl. I | J9: sl. J | K9: sl. K | L9: sl. L | M9: sl. M | N9: sl. N
B10: Výuka B Kč | C10: % | D10: Výuka NM Kč | E10: % | F10: Projekty+BP+DP | G10: Příspěvek na vzděl.č. (B, NM) | H10: DSP | I10: Příspěvek na vzděl.č. (B, NM, DSP) | J10: Podpora doc. a prof. | K10: Část na tarif proděk. | L10: Kvalifikační struktura | M10: Garanti | N10: Příděl 106 (dle výuky mínus odečet ploch)
A11: ITE | B11: ='5_Výuka'!E345 -> 4102198.4 | C11: =B11/$B$16*100 -> 18.807504 | D11: ='5_Výuka'!H345 -> 2192228.6 | E11: =D11/$D$16*100 -> 17.87319 | F11: ='2_Projekty_BP_DP'!J5 -> 332000 | G11: =B11+D11+F11 -> 6626427 | H11: ='3_DSP'!O7 -> 1511979.4 | I11: =G11+H11 -> 8138406.4 | J11: ='4_DOC_PROF'!K7 -> 30000 | K11: ='9_DFM'!C13 -> 0 | L11: ='4a_úvazky-na-FM'!G24 -> 112923.47 | M11: ='6_Garanti'!O42 -> 0 | N11: =I11+J11+K11+L11+M11 -> 8281329.9
A12: MTI | B12: ='5_Výuka'!E346 -> 10842765 | C12: =B12/$B$16*100 -> 49.711236 | D12: ='5_Výuka'!H346 -> 6301126.3 | E12: =D12/$D$16*100 -> 51.372941 | F12: ='2_Projekty_BP_DP'!J6 -> 1732000 | G12: =B12+D12+F12 -> 18875892 | H12: ='3_DSP'!O8 -> 2015972.5 | I12: =G12+H12 -> 20891864 | J12: ='4_DOC_PROF'!K8 -> 30000 | K12: ='9_DFM'!C14 -> 0 | L12: ='4a_úvazky-na-FM'!G25 -> 226808.44 | M12: ='6_Garanti'!O43 -> 0 | N12: =I12+J12+K12+L12+M12 -> 21148673
A13: NTI | B13: ='5_Výuka'!E347 -> 6866534.6 | C13: =B13/$B$16*100 -> 31.48126 | D13: ='5_Výuka'!H347 -> 3772102.8 | E13: =D13/$D$16*100 -> 30.753869 | F13: ='2_Projekty_BP_DP'!J7 -> 666000 | G13: =B13+D13+F13 -> 11304637 | H13: ='3_DSP'!O9 -> 4724935.6 | I13: =G13+H13 -> 16029573 | J13: ='4_DOC_PROF'!K9 -> 0 | K13: ='9_DFM'!C15 -> 202200 | L13: ='4a_úvazky-na-FM'!G26 -> 172910.72 | M13: ='6_Garanti'!O44 -> 0 | N13: =I13+J13+K13+L13+M13 -> 16404684
A14: DFM | H14: ='3_DSP'!O10+0.11 -> 800000 | I14: =G14+H14 -> 800000 | M14: ='6_Garanti'!O46 -> 385344 | N14: =I14+J14+K14+L14+M14 -> 1185344
A15: mimo FM | H15: ='3_DSP'!O16 -> 0 | I15: =G15+H15 -> 0 | N15: =I15+J15+K15+L15+M15 -> 0
B16: =SUM(B11:B14) -> 21811499 | C16: =SUM(C11:C14) -> 100 | D16: =SUM(D11:D14) -> 12265458 | E16: =SUM(E11:E14) -> 100 | F16: =SUM(F11:F14) -> 2730000 | G16: =SUM(G11:G14) -> 36806956 | H16: =SUM(H11:H15) -> 9052887.5 | I16: =SUM(I11:I14) -> 45859844 | J16: =SUM(J11:J14) -> 60000 | K16: =SUM(K11:K14) -> 202200 | L16: =SUM(L11:L14) -> 512642.63 | M16: =SUM(M11:M14) -> 385344 | N16: =SUM(N11:N15) -> 47020030
M17: kontrola | N17: =N16-'0_PRIDEL'!B19 -> 0.10999999

Sheet 11_Celkem_115
A1: Rozpočet FM na rok 2024 - činn. 115 - SGS (Specifický výzkum)
A3: přiděleno "na FM" | B3: ='0_PRIDEL'!B21 -> 4406959.6
A4: na DFM | B4: =E11 -> 334891
A5: na projekty | B5: =B3-B4 -> 4072068.6
F7: DFM, 7817 - Organizace SGS+konference | J7: rozdělení v rámci FM
E8: Účelová podpora činnost 115 | F8: Interní číslo projektu | J8: útvar (sl.D) | K8: sumif (sl.E) | L8: úprava | M8: celkem na pracoviště
D9: DFM 7817 | E9: 109322 | F9: 21068 | G9: organizace | J9: ITE 7620 | K9: =SUMIF($D$9:$D$31,J9,$E$9:$E$31) -> 251318 | M9: =SUM(K9:L9) -> 251318
D10: DFM 7817 | E10: 225569 | F10: 21069 | G10: konference | J10: MTI 7630 | K10: =SUMIF($D$9:$D$31,J10,$E$9:$E$31) -> 1115719 | M10: =SUM(K10:L10) -> 1115719
D11: CELKEM za DFM | E11: =SUM(E9:E10) -> 334891 | J11: NTI 7640 | K11: =SUMIF($D$9:$D$31,J11,$E$9:$E$31) -> 2705032 | M11: =SUM(K11:L11) -> 2705032
E13: =E8 -> Účelová podpora činnost 115 | F13: Interní číslo projektu
D14: ITE 7620 | E14: 125659 | F14: 21476 | J14: DFM 7817 | K14: =SUMIF($D$9:$D$31,J14,$E$9:$E$31) -> 334891 | M14: =SUM(K14:L14) -> 334891
D15: ITE 7620 | E15: 125659 | F15: 21570 | M15: =SUM(M9:M14) -> 4406960
D16: MTI 7630 | E16: 150790 | F16: 21566 | J16: CELKEM za útvary | K16: =SUM(K9:K15) -> 4406960 | L16: =SUM(L9:L15) -> 0 | M16: =SUM(K16:L16) -> 4406960
D17: MTI 7630 | E17: 289015 | F17: 21572 | J17: kontrola | K17: =K16-E36 -> 0
D18: MTI 7630 | E18: 314147 | F18: 21573
D19: MTI 7630 | E19: 173279 | F19: 21578 | J19: příděl na FM | K19: =B3 -> 4406959.6
D20: MTI 7630 | E20: 188488 | F20: 21579 | J20: rozpočtová úprava | K20: =-L16 -> 0
D21: NTI 7640 | E21: 408391 | F21: 21526
D22: NTI 7640 | E22: 354107 | F22: 21527
D23: NTI 7640 | E23: 234832 | F23: 21528
D24: NTI 7640 | E24: 212363 | F24: 21567
D25: NTI 7640 | E25: 138224 | F25: 21568
D26: NTI 7640 | E26: 332996 | F26: 21569
D27: NTI 7640 | E27: 94244 | F27: 21571
D28: NTI 7640 | E28: 194771 | F28: 21574
D29: NTI 7640 | E29: 389542 | F29: 21575
D30: NTI 7640 | E30: 100527 | F30: 21576
D31: NTI 7640 | E31: 245035 | F31: 21577
D32: CELKEM za ústavy | E32: =SUM(E14:E31) -> 4072069
D33: kontrola | E33: =E32-B5 -> 0.40329233
D36: CELKEM | E36: =E32+E11 -> 4406960
D37: kontrola | E37: =E36-B3 -> 0.40329233

Sheet 13_Celoškolská Režie
A1: Rozpočet FM na rok 2024 - rozdělení celoškolské režie
B3: Stanovení režií, RozRez2024.xls | C3: Z toho režie vypočtená Full Costem (FC) | D3: Přepočet na provedené dislokace
A4: FM celkem | B4: ='0_PRIDEL'!H21 -> 22140022 | C4: ='0_PRIDEL'!H19 -> 22264176 | D4: ='0_PRIDEL'!H20 -> -124154.07
B6: DFM + SFM | C6: ITE | D6: MTI | E6: NTI
A7: Režie vypočtená Full Costem | B7: =5105302.29+1108672.27 -> 6213974.6 | C7: =2017492.17+734694.78+5015.38 -> 2757202.3 | D7: =6630302.87+2262872.12 -> 8893175 | E7: =3862665.59+890108.29 -> 4752773.9 | F7: =SUM(B7:E7) -> 22617126 | G7: ř. 32
A8: Studijní režie - služby, 7117 | B8: 448145.38 | F8: =SUM(B8:E8) -> 448145.38
A9: Studijní režie - učebny, 7817 | B9: 5804.65 | F9: =SUM(B9:E9) -> 5804.65
A10: Režie pro veškeré činnosti, 7117 | B10: 4657156.9 | F10: =SUM(B10:E10) -> 4657156.9
A11: Celkem pro přepočet dle studentů | B11: =SUM(B8:B10) -> 5111106.9 | F11: =SUM(B11:E11) -> 5111106.9
A12: Studenti v předmětech vč. DSP se SDZ | C12: 941 | D12: 2128 | E12: 1272 | F12: =SUM(B12:E12) -> 4341
A13: Přepočet režie dle studentů na ústavy | B13: =B12/$F$12*$B$11 -> 0 | C13: =C12/$F$12*$B$11 -> 1107936.3 | D13: =D12/$F$12*$B$11 -> 2505513.8 | E13: =E12/$F$12*$B$11 -> 1497656.8 | F13: =SUM(B13:E13) -> 5111106.9
A15: Režie pro veškeré činnosti, 7817 | B15: 1092908.8 | F15: =SUM(B15:E15) -> 1092908.8
A16: Celkem pro přepočet dle PPV | B16: =B15 -> 1092908.8 | F16: =SUM(B16:E16) -> 1092908.8
A17: Přepočtený počet PP | B17: 5.8 | C17: 18.2 | D17: 43.39 | E17: 33.98 | F17: =SUM(B17:E17) -> 101.37
A18: Přepočet režie dle PPV na pracoviště | B18: =$B$16*B17/$F$17 -> 62532.023 | C18: =$B$16*C17/$F$17 -> 196221.18 | D18: =$B$16*D17/$F$17 -> 467804.22 | E18: =$B$16*E17/$F$17 -> 366351.41 | F18: =SUM(B18:E18) -> 1092908.8
A19: výpočet základní výše režie pro následný dopočet | B19: =B7-B11-B16+B18 -> 72490.813 | C19: =C7+C13+C18 -> 4061359.8 | D19: =D7+D13+D18 -> 11866493 | E19: =E7+E13+E18 -> 6616782.1 | F19: =SUM(B19:E19) -> 22617126 | G19: ZÁKLAD
A20: Procento režie vypočtené metodou FC | B20: =B19/$F$19 -> 0.0032051293 | C20: =C19/$F$19 -> 0.17957011 | D20: =D19/$F$19 -> 0.52466848 | E20: =E19/$F$19 -> 0.29255627 | F20: =SUM(B20:E20) -> 1
A21: Přepočet na provedené dislokace | B21: =B20*$F$21 -> -397.92987 | C21: =C20*$F$21 -> -22294.361 | D21: =D20*$F$21 -> -65139.73 | E21: =E20*$F$21 -> -36322.053 | F21: =D4 -> -124154.07 | G21: DISLOKACE
A22: rozdělení základní režie včetně dislokace | B22: =B19+B21 -> 72092.884 | C22: =C19+C21 -> 4039065.5 | D22: =D19+D21 -> 11801353 | E22: =E19+E21 -> 6580460 | F22: =SUM(B22:E22) -> 22492972
A23: elektrika kvestor nový výpočet | B23: =$F$23*B24 -> 2957.3974 | C23: =$F$23*C24 -> 165690.72 | D23: =$F$23*D24 -> 484115.63 | E23: =$F$23*E24 -> 269943.92 | F23: 922707.67 | G23: ELETRIKA
A24: přepočet dle procenta vypočteného metodou FC | B24: =B20 -> 0.0032051293 | C24: =C20 -> 0.17957011 | D24: =D20 -> 0.52466848 | E24: =E20 -> 0.29255627 | F24: =SUM(B24:E24) -> 1
A25: Přepočet na 2023 s navýšením m2 | B25: =B26*$F$25 -> -4088.6466 | C25: =C26*$F$25 -> -229069.93 | D25: =D26*$F$25 -> -669297.18 | E25: =E26*$F$25 -> -373201.55 | F25: =-(F19+F23-22264176.14) -> -1275657.3 | G25: korekce REK
B26: =B20 -> 0.0032051293 | C26: =C20 -> 0.17957011 | D26: =D20 -> 0.52466848 | E26: =E20 -> 0.29255627 | F26: =SUM(B26:E26) -> 1
A27: POŽADOVANÁ REŽIE CELKEM | B27: =B19+B21+B23+B25 -> 70961.634 | C27: =C19+C21+C23+C25 -> 3975686.3 | D27: =D19+D21+D23+D25 -> 11616172 | E27: =E19+E21+E23+E25 -> 6477202.4 | F27: =SUM(B27:E27) -> 22140022
F32: Režie základ+dislokace+eletrika ZAOKROUHLENO | H32: Režie AS - příspěvek | I32: REŽIE CELKEM
E33: ITE | F33: =CEILING(C27,1)-1 -> 3975686 | H33: 0 | I33: =F33+H33 -> 3975686
E34: MTI | F34: =CEILING(D27,1)-1 -> 11616171 | H34: 0 | I34: =F34+H34 -> 11616171
E35: NTI | F35: =CEILING(E27,1)-1 -> 6477202 | H35: 0 | I35: =F35+H35 -> 6477202
E36: DFM | F36: =CEILING(B27,1)+1 -> 70963 | H36: ='0_PRIDEL'!H22 -> 25000 | I36: =F36+H36 -> 95963
F37: =SUM(F33:F36) -> 22140022 | H37: =SUM(H33:H36) -> 25000 | I37: =SUM(I33:I36) -> 22165022
F38: 22140022
F39: =F38-F37 -> 0

Sheet 12_Celkem_117
A1: Rozpočet FM na rok 2024 - činnost 117 (institucionální podpora z MŠMT)
B3: Příděl dotace 117 celkem | D3: ='0_PRIDEL'!B20 -> 21332321 | E3: celková přidělaná částka z NavRoz2023-kvestor (list 0)
B4: Publikace - vypláceno ústavy | C4: =C15+C16 -> 357000 | D4: =D3-C4 -> 20975321 | E4: strženo PŘED rozdělením na ústavy
B5: Publikace - vypláceno DFM | C5: =C24 -> 0 | D5: =D4-0 -> 20975321 | E5: částka refundována rozpočtovou úpravou - nesnižuje příděl pro rozdělení
B6: přerozdělení Doc/Prof | C6: ='4_DOC_PROF'!I16 -> 60000 | D6: =D4-C6 -> 20915321 | E6: Příděl části dotace podle počtu kvalifikační struktury DOC a PROF (list 4) - strženo PŘED rozdělením na ústavy
B7: kvalif.struktura | C7: ='4a_úvazky-na-FM'!H27 -> 512642.63 | D7: =D6-C7 -> 20402678 | E7: Příděl části dotace podle kvalifikační struktury (list 4a) - strženo PŘED rozdělením na ústavy
B8: Na provoz 117 na DFM | C8: =250000 -> 250000 | D8: =D7-C8 -> 20152678 | E8: strženo PŘED rozdělením na ústavy
B9: Dotace 117 k ROZDĚLENÍ | D9: =D3-C4-C6-C7-C8 -> 20152678 | E9: konečná hodnota pro přepočet na ústavy
D10: =D8-D9 -> 0
A12: Publikační činnost pod ÚSTAVY
B13: Na DSP za publikace (1 měsíc) | C13: Na DSP za publikace (12 měsíců) | F13: Příděl 117 STAB | G13: Příděl 117 MOT | H13: Provoz DFM | I13: Přerozdělení za doc./prof. | J13: Na DSP za publikace (12 měsíců) | K13: Kvalifikační struktura | L13: Příděl 117 PŘED refundací | M13: publikace refundace | N13: Příděl 117 rozdělení FINAL
A14: ITE | B14: =B46 -> 0 | C14: =12*B14 -> 0 | E14: =A14 -> ITE | F14: =$G$34*G35 -> 2970480.1 | G14: =$H$34*H35 -> 4096031.8 | I14: ='4_DOC_PROF'!L7 -> 30000 | J14: =C14 -> 0 | K14: ='4a_úvazky-na-FM'!H24 -> 112923.47 | L14: =SUM(F14:K14) -> 7209435.4 | N14: =L14+M14 -> 7209435.4
A15: MTI | B15: 3750 | C15: =(2*B15)+(10*750) -> 15000 | E15: =A15 -> MTI | F15: =$G$34*G36 -> 4170944.1 | G15: =$H$34*H36 -> 2673252.8 | I15: ='4_DOC_PROF'!L8 -> 30000 | J15: =C15 -> 15000 | K15: ='4a_úvazky-na-FM'!H25 -> 226808.44 | L15: =SUM(F15:K15) -> 7116005.3 | N15: =L15+M15 -> 7116005.3
A16: NTI | B16: 28500 | C16: =12*B16 -> 342000 | E16: =A16 -> NTI | F16: =$G$34*G37 -> 2934914.8 | G16: =$H$34*H37 -> 3307054.5 | I16: ='4_DOC_PROF'!L9 -> 0 | J16: =C16 -> 342000 | K16: ='4a_úvazky-na-FM'!H26 -> 172910.72 | L16: =SUM(F16:K16) -> 6756880 | N16: =L16+M16 -> 6756880
A17: DFM | B17: 0 | C17: =12*B17 -> 0 | E17: =A17 -> DFM | H17: 250000 | J17: 0 | L17: =SUM(F17:K17)-J17 -> 250000 | N17: =L17+M17 -> 250000
B18: =SUM(B14:B17) -> 32250 | C18: =SUM(C14:C17) -> 357000 | F18: =SUM(F8:F17) -> 10076339 | G18: =SUM(G8:G17) -> 10076339 | H18: =SUM(H8:H17) -> 250000 | I18: =SUM(I8:I17) -> 60000 | J18: =SUM(J14:J17) -> 357000 | K18: =SUM(K8:K17) -> 512642.63 | L18: =SUM(L14:L17) -> 21332321 | M18: =SUM(M14:M17) -> 0 | N18: =SUM(N14:N17) -> 21332321
E19: kontrola | F19: =F18-G34 -> 0 | G19: =G18-H34 -> 0 | M19: kontrola | N19: =N18-D3 -> 0
A20: Publikační činnost pod DFM - refundace
A21: DFM (CxI) | B21: 0 | C21: =12*B21 -> 0 | D21: nebude započítáno do rozpočtu, refundace z FP/CXI/NTI
A22: DFM (FP-KCHT) | B22: 0 | C22: =12*B22 -> 0
A23: DFM (REK-NTI) | B23: 0 | C23: =12*B23 -> 0
B24: =SUM(B21:B23) -> 0 | C24: =SUM(C21:C23) -> 0
F31: hodnoty pro přepočet na ústavy
F32: 2024 | G32: STAB | H32: MOT | I32: % vyjádření
G33: 0.5 | H33: =1-G33 -> 0.5
F34: FM celkem | G34: =$D$8*G33 -> 10076339 | H34: =$D$8*H33 -> 10076339 | I34: =H34+G34-D8 -> 0
F35: ITE | G35: 0.29479756 | H35: 0.4065
F36: MTI | G36: 0.41393447 | H36: 0.2653
F37: NTI | G37: 0.29126797 | H37: =1-H35-H36 -> 0.3282
G38: =SUM(G35:G37) -> 1 | H38: =SUM(H35:H37) -> 1
G39: fix | H39: ze souboru M17+ hodnoceni 20xx FM.xlsx od ZK
A45: Částky pro výplatu stipendií za publikační činnost | C45: PUBLIKAČNÍ_ČINNOST_2022.xlsx od SO (Simona)
A46: =A14 -> ITE | B46: 0
A47: =A15 -> MTI | B47: 3000
